Workbook

Sheet README
A1: Healthcare Claims Analytics — Portfolio Project v1
A3: Business Scenario | B3: Fictional healthcare claims operations dataset for a first professional portfolio project.
A4: Dataset Size | B4: 1,500 claims, 300 members, 50 providers, 100 employees, plus a deliberately messy sample.
A5: Tools | B5: Advanced Excel → MySQL → Power BI.
A6: Focus | B6: Claims volume, financial impact, processing time, denials, SLA, department and provider performance.
A7: Privacy | B7: All data is fictional; no real patient or protected health information.
A8: Workflow | B8: Clean data → analyze in Excel → reproduce analysis in MySQL → build Power BI dashboard → document on GitHub.

Sheet Claims
A1: Claim_ID | B1: Member_ID | C1: Provider_ID | D1: Employee_ID | E1: Claim_Received_Date | F1: Service_Date | G1: Claim_Type | H1: Diagnosis_Code | I1: Procedure_Code | J1: Billed_Amount | K1: Allowed_Amount | L1: Paid_Amount | M1: Member_Responsibility | N1: Claim_Status | O1: Denial_Reason | P1: Processing_Days | Q1: Priority | R1: Region | S1: Payment_Date | V1: Claims Overview | W1: Values
A2: C000001 | B2: M0046 | C2: P0013 | D2: E0057 | E2: 46082 | F2: 46081 | G2: Dental | H2: DX-943 | I2: PR-7671 | J2: 37314.32 | K2: 32919.04 | L2: 27329.95 | M2: 5589.09 | N2: Paid | P2: 7 | Q2: Low | R2: Karnataka | S2: 46089 | V2: Total Claims | W2: =COUNTA(Claims[Claim_ID]) -> 1500
A3: C000002 | B3: M0160 | C3: P0046 | D3: E0065 | E3: 46221 | F3: 46217 | G3: Pharmacy | H3: DX-238 | I3: PR-9589 | J3: 41140.36 | K3: 33100.75 | L3: 0 | M3: 33100.75 | N3: Denied | O3: Invalid Procedure Code | P3: 3 | Q3: Low | R3: Delhi | V3: Total Billed Amount | W3: =SUM(Claims[Billed_Amount]) -> 38699572
A4: C000003 | B4: M0026 | C4: P0024 | D4: E0091 | E4: 46068 | F4: 46067 | G4: Dental | H4: DX-380 | I4: PR-7035 | J4: 10435.98 | K4: 6963.81 | L4: 0 | M4: 6963.81 | N4: Denied | O4: Duplicate Claim | P4: 1 | Q4: Medium | R4: Telangana | V4: Total Allowed Amount | W4: =SUM(Claims[Allowed_Amount]) -> 30920113
A5: C000004 | B5: M0229 | C5: P0012 | D5: E0061 | E5: 46129 | F5: 46124 | G5: Vision | H5: DX-452 | I5: PR-3679 | J5: 34218.13 | K5: 24725.39 | L5: 0 | M5: 24725.39 | N5: Denied | O5: Out of Network | P5: 8 | Q5: Medium | R5: Tamil Nadu | V5: Total Paid Amount | W5: =SUM(Claims[Paid_Amount]) -> 15781235
A6: C000005 | B6: M0114 | C6: P0042 | D6: E0029 | E6: 46199 | F6: 46199 | G6: Dental | H6: DX-375 | I6: PR-7709 | J6: 19635 | K6: 13722.36 | L6: 12254.95 | M6: 1467.41 | N6: Paid | P6: 4 | Q6: Low | R6: Delhi | S6: 46203 | V6: Total Member Responsibility | W6: =SUM(Claims[Member_Responsibility]) -> 15138878
A7: C000006 | B7: M0115 | C7: P0017 | D7: E0078 | E7: 46227 | F7: 46222 | G7: Vision | H7: DX-829 | I7: PR-5511 | J7: 45620.01 | K7: 38512.94 | L7: 34672.64 | M7: 3840.3 | N7: Paid | P7: 1 | Q7: Medium | R7: Karnataka | S7: 46228 | V7: Average Processing Days | W7: =AVERAGE(Claims[Processing_Days]) -> 5.3406667
A8: C000007 | B8: M0300 | C8: P0007 | D8: E0001 | E8: 46115 | F8: 46112 | G8: Vision | H8: DX-674 | I8: PR-5631 | J8: 23601.55 | K8: 20135.87 | L8: 19251.46 | M8: 884.41 | N8: Paid | P8: 7 | Q8: Medium | R8: Tamil Nadu | S8: 46122 | V8: Paid Claims | W8: =COUNTIF(Claims[Claim_Status],"Paid") -> 868
A9: C000008 | B9: M0153 | C9: P0013 | D9: E0020 | E9: 46053 | F9: 46050 | G9: Dental | H9: DX-158 | I9: PR-7620 | J9: 49423.87 | K9: 41623.72 | L9: 40182.41 | M9: 1441.31 | N9: Paid | P9: 5 | Q9: Low | R9: Maharashtra | S9: 46058 | V9: Paid Rate | W9: =W8/W2 -> 0.57866667
A10: C000009 | B10: M0215 | C10: P0026 | D10: E0050 | E10: 46198 | F10: 46197 | G10: Medical | H10: DX-697 | I10: PR-4111 | J10: 32942.33 | K10: 31270.2 | L10: 0 | M10: 31270.2 | N10: Pending | P10: 8 | Q10: Medium | R10: Tamil Nadu | V10: Denial Claims | W10: =COUNTIF(Claims[Claim_Status],"Denied") -> 291
A11: C000010 | B11: M0184 | C11: P0033 | D11: E0039 | E11: 46206 | F11: 46205 | G11: Dental | H11: DX-960 | I11: PR-3967 | J11: 32096.52 | K11: 25443.57 | L11: 0 | M11: 25443.57 | N11: Pending | P11: 14 | Q11: Medium | R11: Delhi | V11: Denial Rate | W11: =W10/W2 -> 0.194
A12: C000011 | B12: M0172 | C12: P0042 | D12: E0012 | E12: 46144 | F12: 46143 | G12: Dental | H12: DX-463 | I12: PR-4659 | J12: 36396.74 | K12: 29761.96 | L12: 0 | M12: 29761.96 | N12: Pending | P12: 6 | Q12: Low | R12: Haryana | V12: Pending Claims | W12: =COUNTIF(Claims[Claim_Status],"Pending") -> 258
A13: C000012 | B13: M0061 | C13: P0031 | D13: E0007 | E13: 46104 | F13: 46101 | G13: Medical | H13: DX-583 | I13: PR-4187 | J13: 16900.2 | K13: 12306.18 | L13: 0 | M13: 12306.18 | N13: Denied | O13: Duplicate Claim | P13: 5 | Q13: Low | R13: Delhi | V13: Pending Rate | W13: =W12/W2 -> 0.172
A14: C000013 | B14: M0176 | C14: P0027 | D14: E0073 | E14: 46200 | F14: 46197 | G14: Pharmacy | H14: DX-246 | I14: PR-6183 | J14: 20948.81 | K14: 19089.7 | L14: 15036.85 | M14: 4052.85 | N14: Paid | P14: 4 | Q14: Low | R14: Uttar Pradesh | S14: 46204 | V14: Cancelled Claims | W14: =COUNTIF(Claims[Claim_Status],"Cancelled") -> 83
A15: C000014 | B15: M0232 | C15: P0018 | D15: E0027 | E15: 46222 | F15: 46222 | G15: Dental | H15: DX-690 | I15: PR-3595 | J15: 31736.12 | K15: 22311.99 | L15: 20273.23 | M15: 2038.76 | N15: Paid | P15: 1 | Q15: Medium | R15: Haryana | S15: 46223 | V15: Cancelled Rate | W15: =W14/W2 -> 0.055333333
A16: C000015 | B16: M0197 | C16: P0001 | D16: E0005 | E16: 46218 | F16: 46218 | G16: Dental | H16: DX-848 | I16: PR-7112 | J16: 21968.72 | K16: 17109.74 | L16: 14667.43 | M16: 2442.31 | N16: Paid | P16: 8 | Q16: High | R16: Maharashtra | S16: 46226 | V16: SLA Compliance (<=7 days) | W16: =COUNTIF(Claims[Processing_Days],"<=7")/W2 -> 0.78666667
A17: C000016 | B17: M0160 | C17: P0009 | D17: E0014 | E17: 46220 | F17: 46216 | G17: Pharmacy | H17: DX-615 | I17: PR-6015 | J17: 33999.03 | K17: 28491.39 | L17: 23140.87 | M17: 5350.52 | N17: Paid | P17: 6 | Q17: High | R17: Delhi | S17: 46226
A18: C000017 | B18: M0223 | C18: P0044 | D18: E0018 | E18: 46233 | F18: 46233 | G18: Vision | H18: DX-601 | I18: PR-6885 | J18: 14895.98 | K18: 12934.92 | L18: 11629.69 | M18: 1305.23 | N18: Paid | P18: 6 | Q18: High | R18: Uttar Pradesh | S18: 46239 | V18: Claim Type | W18: Claims | X18: Claim % | Y18: Billed Amount | Z18: Paid Amount | AA18: Denied Claims | AB18: Denial Rate | AC18: Average Processing Days
A19: C000018 | B19: M0259 | C19: P0011 | D19: E0016 | E19: 46233 | F19: 46230 | G19: Vision | H19: DX-828 | I19: PR-1612 | J19: 11603.91 | K19: 10971.08 | L19: 8807.56 | M19: 2163.52 | N19: Paid | P19: 1 | Q19: Medium | R19: Tamil Nadu | S19: 46234 | V19: Medical | W19: =COUNTIF(Claims[Claim_Type],V19) -> 399 | X19: =W19/$W$2 -> 0.266 | Y19: =SUMIF(Claims[Claim_Type],V19,Claims[Billed_Amount]) -> 10429788 | Z19: =SUMIF(Claims[Claim_Type],V19,Claims[Paid_Amount]) -> 3917719.6 | AA19: =COUNTIFS(Claims[Claim_Type],V19,Claims[Claim_Status],"Denied") -> 82 | AB19: =AA19/W19 -> 0.20551378 | AC19: =AVERAGEIF(Claims[Claim_Type],V19,Claims[Processing_Days]) -> 5.5463659
A20: C000019 | B20: M0011 | C20: P0004 | D20: E0089 | E20: 46092 | F20: 46088 | G20: Medical | H20: DX-526 | I20: PR-8279 | J20: 29899.24 | K20: 19864.7 | L20: 0 | M20: 19864.7 | N20: Pending | P20: 5 | Q20: Medium | R20: Delhi | V20: Dental | W20: =COUNTIF(Claims[Claim_Type],V20) -> 353 | X20: =W20/$W$2 -> 0.23533333 | Y20: =SUMIF(Claims[Claim_Type],V20,Claims[Billed_Amount]) -> 8837669.5 | Z20: =SUMIF(Claims[Claim_Type],V20,Claims[Paid_Amount]) -> 3522797.7 | AA20: =COUNTIFS(Claims[Claim_Type],V20,Claims[Claim_Status],"Denied") -> 68 | AB20: =AA20/W20 -> 0.19263456 | AC20: =AVERAGEIF(Claims[Claim_Type],V20,Claims[Processing_Days]) -> 5.5325779
A21: C000020 | B21: M0216 | C21: P0043 | D21: E0013 | E21: 46165 | F21: 46163 | G21: Vision | H21: DX-737 | I21: PR-3247 | J21: 8079.79 | K21: 6936.97 | L21: 6295.84 | M21: 641.13 | N21: Paid | P21: 5 | Q21: Medium | R21: Haryana | S21: 46170 | V21: Vision | W21: =COUNTIF(Claims[Claim_Type],V21) -> 376 | X21: =W21/$W$2 -> 0.25066667 | Y21: =SUMIF(Claims[Claim_Type],V21,Claims[Billed_Amount]) -> 9936667.5 | Z21: =SUMIF(Claims[Claim_Type],V21,Claims[Paid_Amount]) -> 4287879.5 | AA21: =COUNTIFS(Claims[Claim_Type],V21,Claims[Claim_Status],"Denied") -> 72 | AB21: =AA21/W21 -> 0.19148936 | AC21: =AVERAGEIF(Claims[Claim_Type],V21,Claims[Processing_Days]) -> 5.268617
A22: C000021 | B22: M0255 | C22: P0013 | D22: E0078 | E22: 46053 | F22: 46049 | G22: Dental | H22: DX-896 | I22: PR-5308 | J22: 6327.86 | K22: 4329.55 | L22: 0 | M22: 4329.55 | N22: Pending | P22: 5 | Q22: Low | R22: Uttar Pradesh | V22: Pharmacy | W22: =COUNTIF(Claims[Claim_Type],V22) -> 372 | X22: =W22/$W$2 -> 0.248 | Y22: =SUMIF(Claims[Claim_Type],V22,Claims[Billed_Amount]) -> 9495447 | Z22: =SUMIF(Claims[Claim_Type],V22,Claims[Paid_Amount]) -> 4052838 | AA22: =COUNTIFS(Claims[Claim_Type],V22,Claims[Claim_Status],"Denied") -> 69 | AB22: =AA22/W22 -> 0.18548387 | AC22: =AVERAGEIF(Claims[Claim_Type],V22,Claims[Processing_Days]) -> 5.0107527
A23: C000022 | B23: M0170 | C23: P0016 | D23: E0001 | E23: 46119 | F23: 46114 | G23: Medical | H23: DX-787 | I23: PR-2458 | J23: 8438.49 | K23: 6872.66 | L23: 6718.64 | M23: 154.02 | N23: Paid | P23: 8 | Q23: High | R23: Haryana | S23: 46127
A24: C000023 | B24: M0132 | C24: P0042 | D24: E0030 | E24: 46174 | F24: 46169 | G24: Pharmacy | H24: DX-403 | I24: PR-5327 | J24: 47497.58 | K24: 41981.11 | L24: 32273.48 | M24: 9707.63 | N24: Paid | P24: 2 | Q24: Medium | R24: Delhi | S24: 46176
A25: C000024 | B25: M0060 | C25: P0007 | D25: E0098 | E25: 46049 | F25: 46048 | G25: Medical | H25: DX-109 | I25: PR-3267 | J25: 42686.31 | K25: 32358.97 | L25: 0 | M25: 32358.97 | N25: Denied | O25: Duplicate Claim | P25: 6 | Q25: Low | R25: Tamil Nadu | V25: Claim Type | W25: OON Denials | X25: % of OON Denials
A26: C000025 | B26: M0191 | C26: P0022 | D26: E0024 | E26: 46068 | F26: 46066 | G26: Medical | H26: DX-510 | I26: PR-7557 | J26: 22166.87 | K26: 18543.52 | L26: 17980.15 | M26: 563.37 | N26: Paid | P26: 2 | Q26: Medium | R26: Maharashtra | S26: 46070 | V26: Medical | W26: =COUNTIFS(Claims[Claim_Type],V26,Claims[Denial_Reason],"Out of Network") -> 13 | X26: =W26/$W$37 -> 0.29545455
A27: C000026 | B27: M0068 | C27: P0045 | D27: E0093 | E27: 46126 | F27: 46121 | G27: Medical | H27: DX-964 | I27: PR-3611 | J27: 40095.01 | K27: 33866.41 | L27: 0 | M27: 33866.41 | N27: Denied | O27: Invalid Procedure Code | P27: 3 | Q27: High | R27: Karnataka | V27: Dental | W27: =COUNTIFS(Claims[Claim_Type],V27,Claims[Denial_Reason],"Out of Network") -> 10 | X27: =W27/$W$37 -> 0.22727273
A28: C000027 | B28: M0015 | C28: P0044 | D28: E0094 | E28: 46177 | F28: 46174 | G28: Dental | H28: DX-594 | I28: PR-8997 | J28: 34080.46 | K28: 24005.53 | L28: 0 | M28: 24005.53 | N28: Denied | O28: Eligibility Issue | P28: 7 | Q28: High | R28: Karnataka | V28: Vision | W28: =COUNTIFS(Claims[Claim_Type],V28,Claims[Denial_Reason],"Out of Network") -> 11 | X28: =W28/$W$37 -> 0.25
A29: C000028 | B29: M0174 | C29: P0034 | D29: E0067 | E29: 46135 | F29: 46135 | G29: Medical | H29: DX-543 | I29: PR-5072 | J29: 32921.19 | K29: 21520.85 | L29: 20812.45 | M29: 708.4 | N29: Paid | P29: 4 | Q29: Medium | R29: Maharashtra | S29: 46139 | V29: Pharmacy | W29: =COUNTIFS(Claims[Claim_Type],V29,Claims[Denial_Reason],"Out of Network") -> 10 | X29: =W29/$W$37 -> 0.22727273
A30: C000029 | B30: M0028 | C30: P0001 | D30: E0083 | E30: 46197 | F30: 46192 | G30: Dental | H30: DX-617 | I30: PR-8688 | J30: 7858.4 | K30: 7056.3 | L30: 0 | M30: 7056.3 | N30: Pending | P30: 13 | Q30: Medium | R30: Haryana
A31: C000030 | B31: M0260 | C31: P0015 | D31: E0071 | E31: 46065 | F31: 46065 | G31: Pharmacy | H31: DX-512 | I31: PR-4850 | J31: 16371.37 | K31: 12266.55 | L31: 0 | M31: 12266.55 | N31: Denied | O31: Invalid Procedure Code | P31: 5 | Q31: High | R31: Karnataka
A32: C000031 | B32: M0010 | C32: P0007 | D32: E0052 | E32: 46140 | F32: 46136 | G32: Pharmacy | H32: DX-136 | I32: PR-9996 | J32: 42901.17 | K32: 33639.68 | L32: 26228.08 | M32: 7411.6 | N32: Paid | P32: 8 | Q32: High | R32: Haryana | S32: 46148 | V32: Denial Reason | W32: Denied Claims | X32: % of Denials | Y32: Billed Amount | Z32: Average Processing Days
A33: C000032 | B33: M0234 | C33: P0022 | D33: E0047 | E33: 46050 | F33: 46046 | G33: Medical | H33: DX-936 | I33: PR-4652 | J33: 32058.14 | K33: 29398.38 | L33: 0 | M33: 29398.38 | N33: Cancelled | P33: 4 | Q33: Medium | R33: Maharashtra | V33: Eligibility Issue | W33: =COUNTIF(Claims[Denial_Reason],V33) -> 65 | X33: =W33/$W$10 -> 0.2233677 | Y33: =SUMIF(Claims[Denial_Reason],V33,Claims[Billed_Amount]) -> 1612819.8 | Z33: =AVERAGEIF(Claims[Denial_Reason],V33,Claims[Processing_Days]) -> 4.2769231
A34: C000033 | B34: M0059 | C34: P0007 | D34: E0098 | E34: 46170 | F34: 46166 | G34: Dental | H34: DX-102 | I34: PR-6592 | J34: 35974.57 | K34: 27304.28 | L34: 0 | M34: 27304.28 | N34: Pending | P34: 11 | Q34: Medium | R34: Haryana | V34: Missing Documentation | W34: =COUNTIF(Claims[Denial_Reason],V34) -> 63 | X34: =W34/$W$10 -> 0.21649485 | Y34: =SUMIF(Claims[Denial_Reason],V34,Claims[Billed_Amount]) -> 1486274.8 | Z34: =AVERAGEIF(Claims[Denial_Reason],V34,Claims[Processing_Days]) -> 4.7301587
A35: C000034 | B35: M0072 | C35: P0046 | D35: E0096 | E35: 46187 | F35: 46185 | G35: Pharmacy | H35: DX-209 | I35: PR-5166 | J35: 19007.57 | K35: 12961.2 | L35: 12627.05 | M35: 334.15 | N35: Paid | P35: 8 | Q35: Low | R35: Uttar Pradesh | S35: 46195 | V35: Invalid Procedure Code | W35: =COUNTIF(Claims[Denial_Reason],V35) -> 60 | X35: =W35/$W$10 -> 0.20618557 | Y35: =SUMIF(Claims[Denial_Reason],V35,Claims[Billed_Amount]) -> 1592803.5 | Z35: =AVERAGEIF(Claims[Denial_Reason],V35,Claims[Processing_Days]) -> 4.4333333
A36: C000035 | B36: M0056 | C36: P0049 | D36: E0054 | E36: 46071 | F36: 46071 | G36: Medical | H36: DX-748 | I36: PR-3018 | J36: 19948.38 | K36: 15701.65 | L36: 0 | M36: 15701.65 | N36: Denied | O36: Eligibility Issue | P36: 4 | Q36: Medium | R36: Karnataka | V36: Duplicate Claim | W36: =COUNTIF(Claims[Denial_Reason],V36) -> 59 | X36: =W36/$W$10 -> 0.20274914 | Y36: =SUMIF(Claims[Denial_Reason],V36,Claims[Billed_Amount]) -> 1560988.1 | Z36: =AVERAGEIF(Claims[Denial_Reason],V36,Claims[Processing_Days]) -> 4.3389831
A37: C000036 | B37: M0284 | C37: P0028 | D37: E0075 | E37: 46195 | F37: 46191 | G37: Pharmacy | H37: DX-620 | I37: PR-3903 | J37: 7164.48 | K37: 5729.07 | L37: 0 | M37: 5729.07 | N37: Cancelled | P37: 1 | Q37: Low | R37: Telangana | V37: Out of Network | W37: =COUNTIF(Claims[Denial_Reason],V37) -> 44 | X37: =W37/$W$10 -> 0.15120275 | Y37: =SUMIF(Claims[Denial_Reason],V37,Claims[Billed_Amount]) -> 1046057.3 | Z37: =AVERAGEIF(Claims[Denial_Reason],V37,Claims[Processing_Days]) -> 4.9545455
A38: C000037 | B38: M0197 | C38: P0027 | D38: E0078 | E38: 46072 | F38: 46067 | G38: Dental | H38: DX-380 | I38: PR-7518 | J38: 5625.92 | K38: 4766.6 | L38: 0 | M38: 4766.6 | N38: Denied | O38: Out of Network | P38: 6 | Q38: Medium | R38: Maharashtra
A39: C000038 | B39: M0284 | C39: P0041 | D39: E0028 | E39: 46139 | F39: 46138 | G39: Dental | H39: DX-314 | I39: PR-5760 | J39: 30324.96 | K39: 27775.57 | L39: 24389 | M39: 3386.57 | N39: Paid | P39: 6 | Q39: Low | R39: Maharashtra | S39: 46145
A40: C000039 | B40: M0060 | C40: P0049 | D40: E0046 | E40: 46196 | F40: 46195 | G40: Pharmacy | H40: DX-696 | I40: PR-7839 | J40: 32679.28 | K40: 30636.76 | L40: 0 | M40: 30636.76 | N40: Cancelled | P40: 6 | Q40: Low | R40: Tamil Nadu
...

Sheet Pivot Analysis
A1: Claim_Status | B1: Claim / Status
A2: Cancelled | B2: 83
A3: Denied | B3: 291
A4: Paid | B4: 868
A5: Pending | B5: 258
A6: Total Result | B6: 1500
B10: Data
A11: Claim_Type | B11: Claim / Type | C11: Billed Amount | D11: Paid Amount | E11: Avg Processing Days
A12: Dental | B12: 353 | C12: 8837669.5 | D12: 3522797.7 | E12: 5.5325779
A13: Medical | B13: 399 | C13: 10429788 | D13: 3917719.6 | E13: 5.5463659
A14: Pharmacy | B14: 372 | C14: 9495447 | D14: 4052838 | E14: 5.0107527
A15: Vision | B15: 376 | C15: 9936667.5 | D15: 4287879.5 | E15: 5.268617
A16: Total Result | B16: 1500 | C16: 38699572 | D16: 15781235 | E16: 5.3406667
A19: Denial_Reason | B19: Claims
A20: Duplicate Claim | B20: 59
A21: Eligibility Issue | B21: 65
A22: Invalid Procedure Code | B22: 60
A23: Missing Documentation | B23: 63
A24: Out of Network | B24: 44
A25: Total Result | B25: 291
B31: Data
A32: Provider_ID | B32: Count of Claim_ID | C32: Sum of Billed_Amount | D32: Sum of Paid_Amount | E32: Average of Processing_Days
A33: P0001 | B33: 41 | C33: 1019780 | D33: 353902.92 | E33: 5.7804878
A34: P0002 | B34: 24 | C34: 478338.44 | D34: 156495.16 | E34: 6.0833333
A35: P0003 | B35: 25 | C35: 730419.6 | D35: 312510.45 | E35: 5.6
A36: P0004 | B36: 35 | C36: 1105415.4 | D36: 388463.12 | E36: 5.5428571
A37: P0005 | B37: 28 | C37: 678844 | D37: 219972.41 | E37: 6.2142857
A38: P0006 | B38: 35 | C38: 1120529.9 | D38: 558771.01 | E38: 5.1428571
A39: P0007 | B39: 41 | C39: 1069367 | D39: 300190.7 | E39: 5.195122
A40: P0008 | B40: 35 | C40: 828698.06 | D40: 332440.07 | E40: 4.7142857
A41: P0009 | B41: 39 | C41: 1030718.6 | D41: 394624.93 | E41: 5.7179487
A42: P0010 | B42: 36 | C42: 915953.64 | D42: 408147.81 | E42: 5.0277778
A43: P0011 | B43: 27 | C43: 556950.02 | D43: 241726.14 | E43: 4.8518519
A44: P0012 | B44: 40 | C44: 1232066 | D44: 549472.07 | E44: 4.75
... A83: Total Result | B83: 1500 | C83: 38699572 | D83: 15781235 | E83: 5.3406667

Sheet Members
A1: Member_ID | B1: Member_Name | C1: Gender | D1: DOB | E1: State | F1: City | G1: Plan_Type | H1: Policy_Start_Date | I1: Active_Status
A2: M0001 | B2: Arjun Sharma | C2: Female | D2: 27489 | E2: Tamil Nadu | F2: Delhi | G2: Gold | H2: 45960 | I2: Active
A3: M0002 | B3: Kavya Sharma | C3: Male | D3: 23840 | E3: Telangana | F3: Hyderabad | G3: Gold | H3: 45945 | I3: Active
A4: M0003 | B4: Amit Joshi | C4: Female | D4: 27260 | E4: Maharashtra | F4: Gurugram | G4: Gold | H4: 45739 | I4: Active
A5: M0004 | B5: Kavya Kumar | C5: Female | D5: 25318 | E5: Maharashtra | F5: Delhi | G5: Gold | H5: 45852 | I5: Active
A6: M0005 | B6: Arjun Kumar | C6: Female | D6: 35941 | E6: Delhi | F6: Chennai | G6: Standard | H6: 45932 | I6: Active
A7: M0006 | B7: Arjun Patel | C7: Male | D7: 34846 | E7: Tamil Nadu | F7: Hyderabad | G7: Platinum | H7: 45953 | I7: Active
A8: M0007 | B8: Amit Verma | C8: Male | D8: 37371 | E8: Maharashtra | F8: Delhi | G8: Silver | H8: 45709 | I8: Active
A9: M0008 | B9: Pooja Mehta | C9: Female | D9: 36683 | E9: Maharashtra | F9: Mumbai | G9: Silver | H9: 46001 | I9: Active
A10: M0009 | B10: Neha Verma | C10: Male | D10: 34676 | E10: Uttar Pradesh | F10: Bengaluru | G10: Standard | H10: 45796 | I10: Active
A11: M0010 | B11: Rohit Gupta | C11: Female | D11: 23128 | E11: Delhi | F11: Gurugram | G11: Platinum | H11: 45863 | I11: Active
A12: M0011 | B12: Neha Verma | C12: Male | D12: 35410 | E12: Uttar Pradesh | F12: Chennai | G12: Standard | H12: 45860 | I12: Active
A13: M0012 | B13: Ishita Singh | C13: Female | D13: 24952 | E13: Telangana | F13: Hyderabad | G13: Platinum | H13: 45957 | I13: Active
... A301: M0300 | B301: Rahul Verma | C301: Male | D301: 32007 | E301: Telangana | F301: Hyderabad | G301: Standard | H301: 45710 | I301: Active

Sheet Providers
A1: Provider_ID | B1: Provider_Name | C1: Specialty | D1: City | E1: State | F1: Network_Status | G1: Provider_Rating
A2: P0001 | B2: Apollo Hospital 1 | C2: Orthopedics | D2: Hyderabad | E2: Delhi | F2: Out-of-Network | G2: 4.8
A3: P0002 | B3: Apollo Clinic 2 | C3: Pediatrics | D3: Bengaluru | E3: Haryana | F3: In-Network | G3: 4.5
A4: P0003 | B4: City Hospital 3 | C4: Dermatology | D4: Hyderabad | E4: Uttar Pradesh | F4: Out-of-Network | G4: 3.5
A5: P0004 | B5: Fortis Clinic 4 | C5: Orthopedics | D5: Bengaluru | E5: Uttar Pradesh | F5: In-Network | G5: 3.5
A6: P0005 | B6: Fortis Clinic 5 | C6: Orthopedics | D6: Bengaluru | E6: Haryana | F6: In-Network | G6: 3.9
A7: P0006 | B7: Max Healthcare 6 | C7: Dental | D7: Bengaluru | E7: Telangana | F7: In-Network | G7: 4
A8: P0007 | B8: Max Clinic 7 | C8: General Medicine | D8: Bengaluru | E8: Maharashtra | F8: Out-of-Network | G8: 4.6
A9: P0008 | B9: Fortis Clinic 8 | C9: Orthopedics | D9: Bengaluru | E9: Haryana | F9: In-Network | G9: 3.7
A10: P0009 | B10: City Healthcare 9 | C10: Cardiology | D10: Bengaluru | E10: Maharashtra | F10: In-Network | G10: 4.9
A11: P0010 | B11: Fortis Clinic 10 | C11: Dental | D11: Chennai | E11: Tamil Nadu | F11: Out-of-Network | G11: 4.9
A12: P0011 | B12: Metro Hospital 11 | C12: Orthopedics | D12: Bengaluru | E12: Maharashtra | F12: Out-of-Network | G12: 3.9
A13: P0012 | B13: City Hospital 12 | C13: Dermatology | D13: Hyderabad | E13: Uttar Pradesh | F13: In-Network | G13: 4.9
... A51: P0050 | B51: Apollo Hospital 50 | C51: Cardiology | D51: Gurugram | E51: Tamil Nadu | F51: Out-of-Network | G51: 4.7

Sheet Employees
A1: Employee_ID | B1: Employee_Name | C1: Department | D1: Team | E1: Manager | F1: Shift | G1: Location | H1: Joining_Date
A2: E0001 | B2: Nitin Patel | C2: Provider Services | D2: Team B | E2: Manager 2 | F2: Morning | G2: Noida | H2: 45729
A3: E0002 | B3: Sneha Joshi | C3: Finance | D3: Team B | E3: Manager 3 | F3: Night | G3: Bengaluru | H3: 45154
A4: E0003 | B4: Meera Mehta | C4: Appeals | D4: Team A | E4: Manager 2 | F4: Evening | G4: Noida | H4: 45129
A5: E0004 | B5: Rahul Singh | C5: Provider Services | D5: Team B | E5: Manager 3 | F5: Morning | G5: Hyderabad | H5: 45564
A6: E0005 | B6: Rahul Kapoor | C6: Enrollment | D6: Team C | E6: Manager 4 | F6: Evening | G6: Hyderabad | H6: 44716
A7: E0006 | B7: Aditya Patel | C7: Appeals | D7: Team C | E7: Manager 3 | F7: Evening | G7: Hyderabad | H7: 45232
A8: E0007 | B8: Meera Sharma | C8: Enrollment | D8: Team A | E8: Manager 4 | F8: Night | G8: Bengaluru | H8: 44691
A9: E0008 | B9: Rohit Patel | C9: Provider Services | D9: Team D | E9: Manager 2 | F9: Evening | G9: Bengaluru | H9: 45223
A10: E0009 | B10: Priya Kumar | C10: Appeals | D10: Team B | E10: Manager 4 | F10: Evening | G10: Noida | H10: 44656
A11: E0010 | B11: Arjun Malhotra | C11: Claims Processing | D11: Team A | E11: Manager 2 | F11: Evening | G11: Hyderabad | H11: 44563
A12: E0011 | B12: Kavya Gupta | C12: Enrollment | D12: Team B | E12: Manager 3 | F12: Morning | G12: Bengaluru | H12: 44753
A13: E0012 | B13: Sneha Mehta | C13: Claims Processing | D13: Team C | E13: Manager 2 | F13: Morning | G13: Hyderabad | H13: 45187
... A101: E0100 | B101: Sneha Sharma | C101: Finance | D101: Team C | E101: Manager 3 | F101: Evening | G101: Hyderabad | H101: 44763

Sheet Raw_Messy_Data
A1: Claim_ID | B1: Employee_Name | C1: Department | D1: City_Country | E1: Email | F1: Claim_Status | G1: Billed_Amount
A2: C000001 | B2: Rohan Kumar | C2: Provider Services | D2: Mumbai,India | E2: rohan.kumar@example.com | F2: Paid | G2: 37314.32
A3: C000002 | B3: Meera Kumar | C3: Enrollment | D3: Chennai,India | E3: meera.kumar@example.com | F3: Denied | G3: 41140.36
A4: C000003 | B4: Vikas Kapoor | C4: Provider Services | D4: Bengaluru,India | E4: vikas.kapoor@example.com | F4: Denied | G4: 10435.98
A5: C000004 | B5: Rohit Malhotra | C5: Finance | D5: Bengaluru,India | E5: rohit.malhotra@example.com | F5: Denied | G5: 34218.13
A6: C000005 | B6: Kavya Verma | C6: Customer Support | D6: Noida,India | E6: kavya.verma@example.com | F6: Paid | G6: 19635
A7: C000006 | B7: Sneha Joshi | C7: Customer Support | D7: Noida,India | E7: sneha.joshi@example.com | F7: Paid | G7: 45620.01
A8: C000007 | B8: Nitin Patel | C8: Provider Services | D8: Noida,India | E8: nitin.patel@example.com | F8: Paid | G8: 23601.55
A9: C000008 | B9: Karan Mehta | C9: Enrollment | D9: Noida,India | E9: karan.mehta@example.com | F9: Paid | G9: 49423.87
A10: C000009 | B10: Rohan Mehta | C10: Enrollment | D10: Bengaluru,India | E10: rohan...mehta@example.com | F10: Pending | G10: 32942.33
A11: C000010 | B11: Ananya Verma | C11: Appeals | D11: Delhi , India | E11: ananya.verma@example.com | F11: Pending | G11: 32096.52
A12: C000011 | B12: Sneha Mehta | C12: claims processing | D12: Bengaluru,India | E12: sneha.mehta@example.com | F12: Pending | G12: 36396.74
A13: C000012 | B13: Meera Sharma | C13: Enrollment | D13: Bengaluru,India | E13: meera.sharma@example.com | F13: Denied | G13: 16900.2
... A121: C000120 | B121: Aarav Kumar | C121: Finance | D121: Delhi , India | E121: aarav.kumar@example.com | F121: Paid | G121: 11935.39

Sheet Dashboard
A1: Healthcare Claims Analytics — Portfolio Project
A2: Amounts shown in project currency units (source data does not specify a currency).
A3: Key Performance Indicators
A6: Total Claims | B6: =Claims!W2 -> 1500
A7: Total Billed Amount | B7: =Claims!W3 -> 38699572
A8: Total Paid Amount | B8: =Claims!W5 -> 15781235
A9: Pending Claims | B9: =Claims!W12 -> 258
A10: Denial Rate | B10: =Claims!W11 -> 0.194
A11: Average Processing Days | B11: =Claims!W7 -> 5.3406667
A12: SLA Compliance | B12: =Claims!W16 -> 0.78666667
A14: Claim Type Breakdown
A15: Claim Type | B15: Claims | C15: Billed Amount | D15: Paid Amount | E15: Denial Rate | F15: Avg Processing Days
A16: =Claims!V19 -> Medical | B16: =Claims!W19 -> 399 | C16: =Claims!Y19 -> 10429788 | D16: =Claims!Z19 -> 3917719.6 | E16: =Claims!AB19 -> 0.20551378 | F16: =Claims!AC19 -> 5.5463659
A17: =Claims!V20 -> Dental | B17: =Claims!W20 -> 353 | C17: =Claims!Y20 -> 8837669.5 | D17: =Claims!Z20 -> 3522797.7 | E17: =Claims!AB20 -> 0.19263456 | F17: =Claims!AC20 -> 5.5325779
A18: =Claims!V21 -> Vision | B18: =Claims!W21 -> 376 | C18: =Claims!Y21 -> 9936667.5 | D18: =Claims!Z21 -> 4287879.5 | E18: =Claims!AB21 -> 0.19148936 | F18: =Claims!AC21 -> 5.268617
A19: =Claims!V22 -> Pharmacy | B19: =Claims!W22 -> 372 | C19: =Claims!Y22 -> 9495447 | D19: =Claims!Z22 -> 4052838 | E19: =Claims!AB22 -> 0.18548387 | F19: =Claims!AC22 -> 5.0107527
A21: Top Denial Reasons
A22: Denial Reason | B22: Denied Claims | C22: % of Denials | D22: Billed Amount | E22: Avg Processing Days
A23: =Claims!V33 -> Eligibility Issue | B23: =Claims!W33 -> 65 | C23: =Claims!X33 -> 0.2233677 | D23: =Claims!Y33 -> 1612819.8 | E23: =Claims!Z33 -> 4.2769231
A24: =Claims!V34 -> Missing Documentation | B24: =Claims!W34 -> 63 | C24: =Claims!X34 -> 0.21649485 | D24: =Claims!Y34 -> 1486274.8 | E24: =Claims!Z34 -> 4.7301587
A25: =Claims!V35 -> Invalid Procedure Code | B25: =Claims!W35 -> 60 | C25: =Claims!X35 -> 0.20618557 | D25: =Claims!Y35 -> 1592803.5 | E25: =Claims!Z35 -> 4.4333333
A26: =Claims!V36 -> Duplicate Claim | B26: =Claims!W36 -> 59 | C26: =Claims!X36 -> 0.20274914 | D26: =Claims!Y36 -> 1560988.1 | E26: =Claims!Z36 -> 4.3389831
A27: =Claims!V37 -> Out of Network | B27: =Claims!W37 -> 44 | C27: =Claims!X37 -> 0.15120275 | D27: =Claims!Y37 -> 1046057.3 | E27: =Claims!Z37 -> 4.9545455
A29: All KPIs and tables are formula-linked to the Claims table — they recalculate automatically if the underlying data changes.
